EEE.EEEEEEEEEE
======================================================================
ERROR: test_cannot_save_empty_list_items (lists.tests.test_models.ListAndItemModelsTest)
----------------------------------------------------------------------
Traceback (most recent call last):
  File "/home/robert/.virtualenvs/superlists/lib/python3.5/site-packages/django/db/backends/utils.py", line 64, in execute
    return self.cursor.execute(sql, params)
  File "/home/robert/.virtualenvs/superlists/lib/python3.5/site-packages/django/db/backends/sqlite3/base.py", line 337, in execute
    return Database.Cursor.execute(self, query, params)
sqlite3.IntegrityError: NOT NULL constraint failed: lists_list.text

The above exception was the direct cause of the following exception:

Traceback (most recent call last):
  File "/home/robert/Projects/workspace/superlists/lists/tests/test_models.py", line 36, in test_cannot_save_empty_list_items
    list_ = List.objects.create()
  File "/home/robert/.virtualenvs/superlists/lib/python3.5/site-packages/django/db/models/manager.py", line 85, in manager_method
    return getattr(self.get_queryset(), name)(*args, **kwargs)
  File "/home/robert/.virtualenvs/superlists/lib/python3.5/site-packages/django/db/models/query.py", line 399, in create
    obj.save(force_insert=True, using=self.db)
  File "/home/robert/.virtualenvs/superlists/lib/python3.5/site-packages/django/db/models/base.py", line 796, in save
    force_update=force_update, update_fields=update_fields)
  File "/home/robert/.virtualenvs/superlists/lib/python3.5/site-packages/django/db/models/base.py", line 824, in save_base
    updated = self._save_table(raw, cls, force_insert, force_update, using, update_fields)
  File "/home/robert/.virtualenvs/superlists/lib/python3.5/site-packages/django/db/models/base.py", line 908, in _save_table
    result = self._do_insert(cls._base_manager, using, fields, update_pk, raw)
  File "/home/robert/.virtualenvs/superlists/lib/python3.5/site-packages/django/db/models/base.py", line 947, in _do_insert
    using=using, raw=raw)
  File "/home/robert/.virtualenvs/superlists/lib/python3.5/site-packages/django/db/models/manager.py", line 85, in manager_method
    return getattr(self.get_queryset(), name)(*args, **kwargs)
  File "/home/robert/.virtualenvs/superlists/lib/python3.5/site-packages/django/db/models/query.py", line 1045, in _insert
    return query.get_compiler(using=using).execute_sql(return_id)
  File "/home/robert/.virtualenvs/superlists/lib/python3.5/site-packages/django/db/models/sql/compiler.py", line 1054, in execute_sql
    cursor.execute(sql, params)
  File "/home/robert/.virtualenvs/superlists/lib/python3.5/site-packages/django/db/backends/utils.py", line 64, in execute
    return self.cursor.execute(sql, params)
  File "/home/robert/.virtualenvs/superlists/lib/python3.5/site-packages/django/db/utils.py", line 94, in __exit__
    six.reraise(dj_exc_type, dj_exc_value, traceback)
  File "/home/robert/.virtualenvs/superlists/lib/python3.5/site-packages/django/utils/six.py", line 685, in reraise
    raise value.with_traceback(tb)
  File "/home/robert/.virtualenvs/superlists/lib/python3.5/site-packages/django/db/backends/utils.py", line 64, in execute
    return self.cursor.execute(sql, params)
  File "/home/robert/.virtualenvs/superlists/lib/python3.5/site-packages/django/db/backends/sqlite3/base.py", line 337, in execute
    return Database.Cursor.execute(self, query, params)
django.db.utils.IntegrityError: NOT NULL constraint failed: lists_list.text

======================================================================
ERROR: test_get_absolute_url (lists.tests.test_models.ListAndItemModelsTest)
----------------------------------------------------------------------
Traceback (most recent call last):
  File "/home/robert/.virtualenvs/superlists/lib/python3.5/site-packages/django/db/backends/utils.py", line 64, in execute
    return self.cursor.execute(sql, params)
  File "/home/robert/.virtualenvs/superlists/lib/python3.5/site-packages/django/db/backends/sqlite3/base.py", line 337, in execute
    return Database.Cursor.execute(self, query, params)
sqlite3.IntegrityError: NOT NULL constraint failed: lists_list.text

The above exception was the direct cause of the following exception:

Traceback (most recent call last):
  File "/home/robert/Projects/workspace/superlists/lists/tests/test_models.py", line 43, in test_get_absolute_url
    list_ = List.objects.create()
  File "/home/robert/.virtualenvs/superlists/lib/python3.5/site-packages/django/db/models/manager.py", line 85, in manager_method
    return getattr(self.get_queryset(), name)(*args, **kwargs)
  File "/home/robert/.virtualenvs/superlists/lib/python3.5/site-packages/django/db/models/query.py", line 399, in create
    obj.save(force_insert=True, using=self.db)
  File "/home/robert/.virtualenvs/superlists/lib/python3.5/site-packages/django/db/models/base.py", line 796, in save
    force_update=force_update, update_fields=update_fields)
  File "/home/robert/.virtualenvs/superlists/lib/python3.5/site-packages/django/db/models/base.py", line 824, in save_base
    updated = self._save_table(raw, cls, force_insert, force_update, using, update_fields)
  File "/home/robert/.virtualenvs/superlists/lib/python3.5/site-packages/django/db/models/base.py", line 908, in _save_table
    result = self._do_insert(cls._base_manager, using, fields, update_pk, raw)
  File "/home/robert/.virtualenvs/superlists/lib/python3.5/site-packages/django/db/models/base.py", line 947, in _do_insert
    using=using, raw=raw)
  File "/home/robert/.virtualenvs/superlists/lib/python3.5/site-packages/django/db/models/manager.py", line 85, in manager_method
    return getattr(self.get_queryset(), name)(*args, **kwargs)
  File "/home/robert/.virtualenvs/superlists/lib/python3.5/site-packages/django/db/models/query.py", line 1045, in _insert
    return query.get_compiler(using=using).execute_sql(return_id)
  File "/home/robert/.virtualenvs/superlists/lib/python3.5/site-packages/django/db/models/sql/compiler.py", line 1054, in execute_sql
    cursor.execute(sql, params)
  File "/home/robert/.virtualenvs/superlists/lib/python3.5/site-packages/django/db/backends/utils.py", line 64, in execute
    return self.cursor.execute(sql, params)
  File "/home/robert/.virtualenvs/superlists/lib/python3.5/site-packages/django/db/utils.py", line 94, in __exit__
    six.reraise(dj_exc_type, dj_exc_value, traceback)
  File "/home/robert/.virtualenvs/superlists/lib/python3.5/site-packages/django/utils/six.py", line 685, in reraise
    raise value.with_traceback(tb)
  File "/home/robert/.virtualenvs/superlists/lib/python3.5/site-packages/django/db/backends/utils.py", line 64, in execute
    return self.cursor.execute(sql, params)
  File "/home/robert/.virtualenvs/superlists/lib/python3.5/site-packages/django/db/backends/sqlite3/base.py", line 337, in execute
    return Database.Cursor.execute(self, query, params)
django.db.utils.IntegrityError: NOT NULL constraint failed: lists_list.text

======================================================================
ERROR: test_saving_and_retrieving_items (lists.tests.test_models.ListAndItemModelsTest)
----------------------------------------------------------------------
Traceback (most recent call last):
  File "/home/robert/.virtualenvs/superlists/lib/python3.5/site-packages/django/db/backends/utils.py", line 64, in execute
    return self.cursor.execute(sql, params)
  File "/home/robert/.virtualenvs/superlists/lib/python3.5/site-packages/django/db/backends/sqlite3/base.py", line 337, in execute
    return Database.Cursor.execute(self, query, params)
sqlite3.IntegrityError: NOT NULL constraint failed: lists_list.text

The above exception was the direct cause of the following exception:

Traceback (most recent call last):
  File "/home/robert/Projects/workspace/superlists/lists/tests/test_models.py", line 10, in test_saving_and_retrieving_items
    list_.save()
  File "/home/robert/.virtualenvs/superlists/lib/python3.5/site-packages/django/db/models/base.py", line 796, in save
    force_update=force_update, update_fields=update_fields)
  File "/home/robert/.virtualenvs/superlists/lib/python3.5/site-packages/django/db/models/base.py", line 824, in save_base
    updated = self._save_table(raw, cls, force_insert, force_update, using, update_fields)
  File "/home/robert/.virtualenvs/superlists/lib/python3.5/site-packages/django/db/models/base.py", line 908, in _save_table
    result = self._do_insert(cls._base_manager, using, fields, update_pk, raw)
  File "/home/robert/.virtualenvs/superlists/lib/python3.5/site-packages/django/db/models/base.py", line 947, in _do_insert
    using=using, raw=raw)
  File "/home/robert/.virtualenvs/superlists/lib/python3.5/site-packages/django/db/models/manager.py", line 85, in manager_method
    return getattr(self.get_queryset(), name)(*args, **kwargs)
  File "/home/robert/.virtualenvs/superlists/lib/python3.5/site-packages/django/db/models/query.py", line 1045, in _insert
    return query.get_compiler(using=using).execute_sql(return_id)
  File "/home/robert/.virtualenvs/superlists/lib/python3.5/site-packages/django/db/models/sql/compiler.py", line 1054, in execute_sql
    cursor.execute(sql, params)
  File "/home/robert/.virtualenvs/superlists/lib/python3.5/site-packages/django/db/backends/utils.py", line 64, in execute
    return self.cursor.execute(sql, params)
  File "/home/robert/.virtualenvs/superlists/lib/python3.5/site-packages/django/db/utils.py", line 94, in __exit__
    six.reraise(dj_exc_type, dj_exc_value, traceback)
  File "/home/robert/.virtualenvs/superlists/lib/python3.5/site-packages/django/utils/six.py", line 685, in reraise
    raise value.with_traceback(tb)
  File "/home/robert/.virtualenvs/superlists/lib/python3.5/site-packages/django/db/backends/utils.py", line 64, in execute
    return self.cursor.execute(sql, params)
  File "/home/robert/.virtualenvs/superlists/lib/python3.5/site-packages/django/db/backends/sqlite3/base.py", line 337, in execute
    return Database.Cursor.execute(self, query, params)
django.db.utils.IntegrityError: NOT NULL constraint failed: lists_list.text

======================================================================
ERROR: test_can_save_POST_request_to_existing_list (lists.tests.test_views.ListViewTest)
----------------------------------------------------------------------
Traceback (most recent call last):
  File "/home/robert/.virtualenvs/superlists/lib/python3.5/site-packages/django/db/backends/utils.py", line 64, in execute
    return self.cursor.execute(sql, params)
  File "/home/robert/.virtualenvs/superlists/lib/python3.5/site-packages/django/db/backends/sqlite3/base.py", line 337, in execute
    return Database.Cursor.execute(self, query, params)
sqlite3.IntegrityError: NOT NULL constraint failed: lists_list.text

The above exception was the direct cause of the following exception:

Traceback (most recent call last):
  File "/home/robert/Projects/workspace/superlists/lists/tests/test_views.py", line 42, in test_can_save_POST_request_to_existing_list
    other_list = List.objects.create()
  File "/home/robert/.virtualenvs/superlists/lib/python3.5/site-packages/django/db/models/manager.py", line 85, in manager_method
    return getattr(self.get_queryset(), name)(*args, **kwargs)
  File "/home/robert/.virtualenvs/superlists/lib/python3.5/site-packages/django/db/models/query.py", line 399, in create
    obj.save(force_insert=True, using=self.db)
  File "/home/robert/.virtualenvs/superlists/lib/python3.5/site-packages/django/db/models/base.py", line 796, in save
    force_update=force_update, update_fields=update_fields)
  File "/home/robert/.virtualenvs/superlists/lib/python3.5/site-packages/django/db/models/base.py", line 824, in save_base
    updated = self._save_table(raw, cls, force_insert, force_update, using, update_fields)
  File "/home/robert/.virtualenvs/superlists/lib/python3.5/site-packages/django/db/models/base.py", line 908, in _save_table
    result = self._do_insert(cls._base_manager, using, fields, update_pk, raw)
  File "/home/robert/.virtualenvs/superlists/lib/python3.5/site-packages/django/db/models/base.py", line 947, in _do_insert
    using=using, raw=raw)
  File "/home/robert/.virtualenvs/superlists/lib/python3.5/site-packages/django/db/models/manager.py", line 85, in manager_method
    return getattr(self.get_queryset(), name)(*args, **kwargs)
  File "/home/robert/.virtualenvs/superlists/lib/python3.5/site-packages/django/db/models/query.py", line 1045, in _insert
    return query.get_compiler(using=using).execute_sql(return_id)
  File "/home/robert/.virtualenvs/superlists/lib/python3.5/site-packages/django/db/models/sql/compiler.py", line 1054, in execute_sql
    cursor.execute(sql, params)
  File "/home/robert/.virtualenvs/superlists/lib/python3.5/site-packages/django/db/backends/utils.py", line 64, in execute
    return self.cursor.execute(sql, params)
  File "/home/robert/.virtualenvs/superlists/lib/python3.5/site-packages/django/db/utils.py", line 94, in __exit__
    six.reraise(dj_exc_type, dj_exc_value, traceback)
  File "/home/robert/.virtualenvs/superlists/lib/python3.5/site-packages/django/utils/six.py", line 685, in reraise
    raise value.with_traceback(tb)
  File "/home/robert/.virtualenvs/superlists/lib/python3.5/site-packages/django/db/backends/utils.py", line 64, in execute
    return self.cursor.execute(sql, params)
  File "/home/robert/.virtualenvs/superlists/lib/python3.5/site-packages/django/db/backends/sqlite3/base.py", line 337, in execute
    return Database.Cursor.execute(self, query, params)
django.db.utils.IntegrityError: NOT NULL constraint failed: lists_list.text

======================================================================
ERROR: test_displays_all_items (lists.tests.test_views.ListViewTest)
----------------------------------------------------------------------
Traceback (most recent call last):
  File "/home/robert/.virtualenvs/superlists/lib/python3.5/site-packages/django/db/backends/utils.py", line 64, in execute
    return self.cursor.execute(sql, params)
  File "/home/robert/.virtualenvs/superlists/lib/python3.5/site-packages/django/db/backends/sqlite3/base.py", line 337, in execute
    return Database.Cursor.execute(self, query, params)
sqlite3.IntegrityError: NOT NULL constraint failed: lists_list.text

The above exception was the direct cause of the following exception:

Traceback (most recent call last):
  File "/home/robert/Projects/workspace/superlists/lists/tests/test_views.py", line 21, in test_displays_all_items
    correct_list = List.objects.create()
  File "/home/robert/.virtualenvs/superlists/lib/python3.5/site-packages/django/db/models/manager.py", line 85, in manager_method
    return getattr(self.get_queryset(), name)(*args, **kwargs)
  File "/home/robert/.virtualenvs/superlists/lib/python3.5/site-packages/django/db/models/query.py", line 399, in create
    obj.save(force_insert=True, using=self.db)
  File "/home/robert/.virtualenvs/superlists/lib/python3.5/site-packages/django/db/models/base.py", line 796, in save
    force_update=force_update, update_fields=update_fields)
  File "/home/robert/.virtualenvs/superlists/lib/python3.5/site-packages/django/db/models/base.py", line 824, in save_base
    updated = self._save_table(raw, cls, force_insert, force_update, using, update_fields)
  File "/home/robert/.virtualenvs/superlists/lib/python3.5/site-packages/django/db/models/base.py", line 908, in _save_table
    result = self._do_insert(cls._base_manager, using, fields, update_pk, raw)
  File "/home/robert/.virtualenvs/superlists/lib/python3.5/site-packages/django/db/models/base.py", line 947, in _do_insert
    using=using, raw=raw)
  File "/home/robert/.virtualenvs/superlists/lib/python3.5/site-packages/django/db/models/manager.py", line 85, in manager_method
    return getattr(self.get_queryset(), name)(*args, **kwargs)
  File "/home/robert/.virtualenvs/superlists/lib/python3.5/site-packages/django/db/models/query.py", line 1045, in _insert
    return query.get_compiler(using=using).execute_sql(return_id)
  File "/home/robert/.virtualenvs/superlists/lib/python3.5/site-packages/django/db/models/sql/compiler.py", line 1054, in execute_sql
    cursor.execute(sql, params)
  File "/home/robert/.virtualenvs/superlists/lib/python3.5/site-packages/django/db/backends/utils.py", line 64, in execute
    return self.cursor.execute(sql, params)
  File "/home/robert/.virtualenvs/superlists/lib/python3.5/site-packages/django/db/utils.py", line 94, in __exit__
    six.reraise(dj_exc_type, dj_exc_value, traceback)
  File "/home/robert/.virtualenvs/superlists/lib/python3.5/site-packages/django/utils/six.py", line 685, in reraise
    raise value.with_traceback(tb)
  File "/home/robert/.virtualenvs/superlists/lib/python3.5/site-packages/django/db/backends/utils.py", line 64, in execute
    return self.cursor.execute(sql, params)
  File "/home/robert/.virtualenvs/superlists/lib/python3.5/site-packages/django/db/backends/sqlite3/base.py", line 337, in execute
    return Database.Cursor.execute(self, query, params)
django.db.utils.IntegrityError: NOT NULL constraint failed: lists_list.text

======================================================================
ERROR: test_passes_correct_list_to_template (lists.tests.test_views.ListViewTest)
----------------------------------------------------------------------
Traceback (most recent call last):
  File "/home/robert/.virtualenvs/superlists/lib/python3.5/site-packages/django/db/backends/utils.py", line 64, in execute
    return self.cursor.execute(sql, params)
  File "/home/robert/.virtualenvs/superlists/lib/python3.5/site-packages/django/db/backends/sqlite3/base.py", line 337, in execute
    return Database.Cursor.execute(self, query, params)
sqlite3.IntegrityError: NOT NULL constraint failed: lists_list.text

The above exception was the direct cause of the following exception:

Traceback (most recent call last):
  File "/home/robert/Projects/workspace/superlists/lists/tests/test_views.py", line 36, in test_passes_correct_list_to_template
    other_list = List.objects.create()
  File "/home/robert/.virtualenvs/superlists/lib/python3.5/site-packages/django/db/models/manager.py", line 85, in manager_method
    return getattr(self.get_queryset(), name)(*args, **kwargs)
  File "/home/robert/.virtualenvs/superlists/lib/python3.5/site-packages/django/db/models/query.py", line 399, in create
    obj.save(force_insert=True, using=self.db)
  File "/home/robert/.virtualenvs/superlists/lib/python3.5/site-packages/django/db/models/base.py", line 796, in save
    force_update=force_update, update_fields=update_fields)
  File "/home/robert/.virtualenvs/superlists/lib/python3.5/site-packages/django/db/models/base.py", line 824, in save_base
    updated = self._save_table(raw, cls, force_insert, force_update, using, update_fields)
  File "/home/robert/.virtualenvs/superlists/lib/python3.5/site-packages/django/db/models/base.py", line 908, in _save_table
    result = self._do_insert(cls._base_manager, using, fields, update_pk, raw)
  File "/home/robert/.virtualenvs/superlists/lib/python3.5/site-packages/django/db/models/base.py", line 947, in _do_insert
    using=using, raw=raw)
  File "/home/robert/.virtualenvs/superlists/lib/python3.5/site-packages/django/db/models/manager.py", line 85, in manager_method
    return getattr(self.get_queryset(), name)(*args, **kwargs)
  File "/home/robert/.virtualenvs/superlists/lib/python3.5/site-packages/django/db/models/query.py", line 1045, in _insert
    return query.get_compiler(using=using).execute_sql(return_id)
  File "/home/robert/.virtualenvs/superlists/lib/python3.5/site-packages/django/db/models/sql/compiler.py", line 1054, in execute_sql
    cursor.execute(sql, params)
  File "/home/robert/.virtualenvs/superlists/lib/python3.5/site-packages/django/db/backends/utils.py", line 64, in execute
    return self.cursor.execute(sql, params)
  File "/home/robert/.virtualenvs/superlists/lib/python3.5/site-packages/django/db/utils.py", line 94, in __exit__
    six.reraise(dj_exc_type, dj_exc_value, traceback)
  File "/home/robert/.virtualenvs/superlists/lib/python3.5/site-packages/django/utils/six.py", line 685, in reraise
    raise value.with_traceback(tb)
  File "/home/robert/.virtualenvs/superlists/lib/python3.5/site-packages/django/db/backends/utils.py", line 64, in execute
    return self.cursor.execute(sql, params)
  File "/home/robert/.virtualenvs/superlists/lib/python3.5/site-packages/django/db/backends/sqlite3/base.py", line 337, in execute
    return Database.Cursor.execute(self, query, params)
django.db.utils.IntegrityError: NOT NULL constraint failed: lists_list.text

======================================================================
ERROR: test_redirects_to_list_view (lists.tests.test_views.ListViewTest)
----------------------------------------------------------------------
Traceback (most recent call last):
  File "/home/robert/.virtualenvs/superlists/lib/python3.5/site-packages/django/db/backends/utils.py", line 64, in execute
    return self.cursor.execute(sql, params)
  File "/home/robert/.virtualenvs/superlists/lib/python3.5/site-packages/django/db/backends/sqlite3/base.py", line 337, in execute
    return Database.Cursor.execute(self, query, params)
sqlite3.IntegrityError: NOT NULL constraint failed: lists_list.text

The above exception was the direct cause of the following exception:

Traceback (most recent call last):
  File "/home/robert/Projects/workspace/superlists/lists/tests/test_views.py", line 56, in test_redirects_to_list_view
    other_list = List.objects.create()
  File "/home/robert/.virtualenvs/superlists/lib/python3.5/site-packages/django/db/models/manager.py", line 85, in manager_method
    return getattr(self.get_queryset(), name)(*args, **kwargs)
  File "/home/robert/.virtualenvs/superlists/lib/python3.5/site-packages/django/db/models/query.py", line 399, in create
    obj.save(force_insert=True, using=self.db)
  File "/home/robert/.virtualenvs/superlists/lib/python3.5/site-packages/django/db/models/base.py", line 796, in save
    force_update=force_update, update_fields=update_fields)
  File "/home/robert/.virtualenvs/superlists/lib/python3.5/site-packages/django/db/models/base.py", line 824, in save_base
    updated = self._save_table(raw, cls, force_insert, force_update, using, update_fields)
  File "/home/robert/.virtualenvs/superlists/lib/python3.5/site-packages/django/db/models/base.py", line 908, in _save_table
    result = self._do_insert(cls._base_manager, using, fields, update_pk, raw)
  File "/home/robert/.virtualenvs/superlists/lib/python3.5/site-packages/django/db/models/base.py", line 947, in _do_insert
    using=using, raw=raw)
  File "/home/robert/.virtualenvs/superlists/lib/python3.5/site-packages/django/db/models/manager.py", line 85, in manager_method
    return getattr(self.get_queryset(), name)(*args, **kwargs)
  File "/home/robert/.virtualenvs/superlists/lib/python3.5/site-packages/django/db/models/query.py", line 1045, in _insert
    return query.get_compiler(using=using).execute_sql(return_id)
  File "/home/robert/.virtualenvs/superlists/lib/python3.5/site-packages/django/db/models/sql/compiler.py", line 1054, in execute_sql
    cursor.execute(sql, params)
  File "/home/robert/.virtualenvs/superlists/lib/python3.5/site-packages/django/db/backends/utils.py", line 64, in execute
    return self.cursor.execute(sql, params)
  File "/home/robert/.virtualenvs/superlists/lib/python3.5/site-packages/django/db/utils.py", line 94, in __exit__
    six.reraise(dj_exc_type, dj_exc_value, traceback)
  File "/home/robert/.virtualenvs/superlists/lib/python3.5/site-packages/django/utils/six.py", line 685, in reraise
    raise value.with_traceback(tb)
  File "/home/robert/.virtualenvs/superlists/lib/python3.5/site-packages/django/db/backends/utils.py", line 64, in execute
    return self.cursor.execute(sql, params)
  File "/home/robert/.virtualenvs/superlists/lib/python3.5/site-packages/django/db/backends/sqlite3/base.py", line 337, in execute
    return Database.Cursor.execute(self, query, params)
django.db.utils.IntegrityError: NOT NULL constraint failed: lists_list.text

======================================================================
ERROR: test_uses_list_template (lists.tests.test_views.ListViewTest)
----------------------------------------------------------------------
Traceback (most recent call last):
  File "/home/robert/.virtualenvs/superlists/lib/python3.5/site-packages/django/db/backends/utils.py", line 64, in execute
    return self.cursor.execute(sql, params)
  File "/home/robert/.virtualenvs/superlists/lib/python3.5/site-packages/django/db/backends/sqlite3/base.py", line 337, in execute
    return Database.Cursor.execute(self, query, params)
sqlite3.IntegrityError: NOT NULL constraint failed: lists_list.text

The above exception was the direct cause of the following exception:

Traceback (most recent call last):
  File "/home/robert/Projects/workspace/superlists/lists/tests/test_views.py", line 16, in test_uses_list_template
    list_ = List.objects.create()
  File "/home/robert/.virtualenvs/superlists/lib/python3.5/site-packages/django/db/models/manager.py", line 85, in manager_method
    return getattr(self.get_queryset(), name)(*args, **kwargs)
  File "/home/robert/.virtualenvs/superlists/lib/python3.5/site-packages/django/db/models/query.py", line 399, in create
    obj.save(force_insert=True, using=self.db)
  File "/home/robert/.virtualenvs/superlists/lib/python3.5/site-packages/django/db/models/base.py", line 796, in save
    force_update=force_update, update_fields=update_fields)
  File "/home/robert/.virtualenvs/superlists/lib/python3.5/site-packages/django/db/models/base.py", line 824, in save_base
    updated = self._save_table(raw, cls, force_insert, force_update, using, update_fields)
  File "/home/robert/.virtualenvs/superlists/lib/python3.5/site-packages/django/db/models/base.py", line 908, in _save_table
    result = self._do_insert(cls._base_manager, using, fields, update_pk, raw)
  File "/home/robert/.virtualenvs/superlists/lib/python3.5/site-packages/django/db/models/base.py", line 947, in _do_insert
    using=using, raw=raw)
  File "/home/robert/.virtualenvs/superlists/lib/python3.5/site-packages/django/db/models/manager.py", line 85, in manager_method
    return getattr(self.get_queryset(), name)(*args, **kwargs)
  File "/home/robert/.virtualenvs/superlists/lib/python3.5/site-packages/django/db/models/query.py", line 1045, in _insert
    return query.get_compiler(using=using).execute_sql(return_id)
  File "/home/robert/.virtualenvs/superlists/lib/python3.5/site-packages/django/db/models/sql/compiler.py", line 1054, in execute_sql
    cursor.execute(sql, params)
  File "/home/robert/.virtualenvs/superlists/lib/python3.5/site-packages/django/db/backends/utils.py", line 64, in execute
    return self.cursor.execute(sql, params)
  File "/home/robert/.virtualenvs/superlists/lib/python3.5/site-packages/django/db/utils.py", line 94, in __exit__
    six.reraise(dj_exc_type, dj_exc_value, traceback)
  File "/home/robert/.virtualenvs/superlists/lib/python3.5/site-packages/django/utils/six.py", line 685, in reraise
    raise value.with_traceback(tb)
  File "/home/robert/.virtualenvs/superlists/lib/python3.5/site-packages/django/db/backends/utils.py", line 64, in execute
    return self.cursor.execute(sql, params)
  File "/home/robert/.virtualenvs/superlists/lib/python3.5/site-packages/django/db/backends/sqlite3/base.py", line 337, in execute
    return Database.Cursor.execute(self, query, params)
django.db.utils.IntegrityError: NOT NULL constraint failed: lists_list.text

======================================================================
ERROR: test_validation_errors_end_up_on_lists_page (lists.tests.test_views.ListViewTest)
----------------------------------------------------------------------
Traceback (most recent call last):
  File "/home/robert/.virtualenvs/superlists/lib/python3.5/site-packages/django/db/backends/utils.py", line 64, in execute
    return self.cursor.execute(sql, params)
  File "/home/robert/.virtualenvs/superlists/lib/python3.5/site-packages/django/db/backends/sqlite3/base.py", line 337, in execute
    return Database.Cursor.execute(self, query, params)
sqlite3.IntegrityError: NOT NULL constraint failed: lists_list.text

The above exception was the direct cause of the following exception:

Traceback (most recent call last):
  File "/home/robert/Projects/workspace/superlists/lists/tests/test_views.py", line 67, in test_validation_errors_end_up_on_lists_page
    list_ = List.objects.create()
  File "/home/robert/.virtualenvs/superlists/lib/python3.5/site-packages/django/db/models/manager.py", line 85, in manager_method
    return getattr(self.get_queryset(), name)(*args, **kwargs)
  File "/home/robert/.virtualenvs/superlists/lib/python3.5/site-packages/django/db/models/query.py", line 399, in create
    obj.save(force_insert=True, using=self.db)
  File "/home/robert/.virtualenvs/superlists/lib/python3.5/site-packages/django/db/models/base.py", line 796, in save
    force_update=force_update, update_fields=update_fields)
  File "/home/robert/.virtualenvs/superlists/lib/python3.5/site-packages/django/db/models/base.py", line 824, in save_base
    updated = self._save_table(raw, cls, force_insert, force_update, using, update_fields)
  File "/home/robert/.virtualenvs/superlists/lib/python3.5/site-packages/django/db/models/base.py", line 908, in _save_table
    result = self._do_insert(cls._base_manager, using, fields, update_pk, raw)
  File "/home/robert/.virtualenvs/superlists/lib/python3.5/site-packages/django/db/models/base.py", line 947, in _do_insert
    using=using, raw=raw)
  File "/home/robert/.virtualenvs/superlists/lib/python3.5/site-packages/django/db/models/manager.py", line 85, in manager_method
    return getattr(self.get_queryset(), name)(*args, **kwargs)
  File "/home/robert/.virtualenvs/superlists/lib/python3.5/site-packages/django/db/models/query.py", line 1045, in _insert
    return query.get_compiler(using=using).execute_sql(return_id)
  File "/home/robert/.virtualenvs/superlists/lib/python3.5/site-packages/django/db/models/sql/compiler.py", line 1054, in execute_sql
    cursor.execute(sql, params)
  File "/home/robert/.virtualenvs/superlists/lib/python3.5/site-packages/django/db/backends/utils.py", line 64, in execute
    return self.cursor.execute(sql, params)
  File "/home/robert/.virtualenvs/superlists/lib/python3.5/site-packages/django/db/utils.py", line 94, in __exit__
    six.reraise(dj_exc_type, dj_exc_value, traceback)
  File "/home/robert/.virtualenvs/superlists/lib/python3.5/site-packages/django/utils/six.py", line 685, in reraise
    raise value.with_traceback(tb)
  File "/home/robert/.virtualenvs/superlists/lib/python3.5/site-packages/django/db/backends/utils.py", line 64, in execute
    return self.cursor.execute(sql, params)
  File "/home/robert/.virtualenvs/superlists/lib/python3.5/site-packages/django/db/backends/sqlite3/base.py", line 337, in execute
    return Database.Cursor.execute(self, query, params)
django.db.utils.IntegrityError: NOT NULL constraint failed: lists_list.text

======================================================================
ERROR: test_can_save_POST_request (lists.tests.test_views.NewListTest)
----------------------------------------------------------------------
Traceback (most recent call last):
  File "/home/robert/.virtualenvs/superlists/lib/python3.5/site-packages/django/db/backends/utils.py", line 64, in execute
    return self.cursor.execute(sql, params)
  File "/home/robert/.virtualenvs/superlists/lib/python3.5/site-packages/django/db/backends/sqlite3/base.py", line 337, in execute
    return Database.Cursor.execute(self, query, params)
sqlite3.IntegrityError: NOT NULL constraint failed: lists_list.text

The above exception was the direct cause of the following exception:

Traceback (most recent call last):
  File "/home/robert/Projects/workspace/superlists/lists/tests/test_views.py", line 82, in test_can_save_POST_request
    '/lists/new', data = {'item_text': 'A new list item'}
  File "/home/robert/.virtualenvs/superlists/lib/python3.5/site-packages/django/test/client.py", line 541, in post
    secure=secure, **extra)
  File "/home/robert/.virtualenvs/superlists/lib/python3.5/site-packages/django/test/client.py", line 343, in post
    secure=secure, **extra)
  File "/home/robert/.virtualenvs/superlists/lib/python3.5/site-packages/django/test/client.py", line 409, in generic
    return self.request(**r)
  File "/home/robert/.virtualenvs/superlists/lib/python3.5/site-packages/django/test/client.py", line 494, in request
    six.reraise(*exc_info)
  File "/home/robert/.virtualenvs/superlists/lib/python3.5/site-packages/django/utils/six.py", line 686, in reraise
    raise value
  File "/home/robert/.virtualenvs/superlists/lib/python3.5/site-packages/django/core/handlers/exception.py", line 39, in inner
    response = get_response(request)
  File "/home/robert/.virtualenvs/superlists/lib/python3.5/site-packages/django/core/handlers/base.py", line 187, in _get_response
    response = self.process_exception_by_middleware(e, request)
  File "/home/robert/.virtualenvs/superlists/lib/python3.5/site-packages/django/core/handlers/base.py", line 185, in _get_response
    response = wrapped_callback(request, *callback_args, **callback_kwargs)
  File "/home/robert/Projects/workspace/superlists/lists/views.py", line 24, in new_list
    list_ = List.objects.create()
  File "/home/robert/.virtualenvs/superlists/lib/python3.5/site-packages/django/db/models/manager.py", line 85, in manager_method
    return getattr(self.get_queryset(), name)(*args, **kwargs)
  File "/home/robert/.virtualenvs/superlists/lib/python3.5/site-packages/django/db/models/query.py", line 399, in create
    obj.save(force_insert=True, using=self.db)
  File "/home/robert/.virtualenvs/superlists/lib/python3.5/site-packages/django/db/models/base.py", line 796, in save
    force_update=force_update, update_fields=update_fields)
  File "/home/robert/.virtualenvs/superlists/lib/python3.5/site-packages/django/db/models/base.py", line 824, in save_base
    updated = self._save_table(raw, cls, force_insert, force_update, using, update_fields)
  File "/home/robert/.virtualenvs/superlists/lib/python3.5/site-packages/django/db/models/base.py", line 908, in _save_table
    result = self._do_insert(cls._base_manager, using, fields, update_pk, raw)
  File "/home/robert/.virtualenvs/superlists/lib/python3.5/site-packages/django/db/models/base.py", line 947, in _do_insert
    using=using, raw=raw)
  File "/home/robert/.virtualenvs/superlists/lib/python3.5/site-packages/django/db/models/manager.py", line 85, in manager_method
    return getattr(self.get_queryset(), name)(*args, **kwargs)
  File "/home/robert/.virtualenvs/superlists/lib/python3.5/site-packages/django/db/models/query.py", line 1045, in _insert
    return query.get_compiler(using=using).execute_sql(return_id)
  File "/home/robert/.virtualenvs/superlists/lib/python3.5/site-packages/django/db/models/sql/compiler.py", line 1054, in execute_sql
    cursor.execute(sql, params)
  File "/home/robert/.virtualenvs/superlists/lib/python3.5/site-packages/django/db/backends/utils.py", line 64, in execute
    return self.cursor.execute(sql, params)
  File "/home/robert/.virtualenvs/superlists/lib/python3.5/site-packages/django/db/utils.py", line 94, in __exit__
    six.reraise(dj_exc_type, dj_exc_value, traceback)
  File "/home/robert/.virtualenvs/superlists/lib/python3.5/site-packages/django/utils/six.py", line 685, in reraise
    raise value.with_traceback(tb)
  File "/home/robert/.virtualenvs/superlists/lib/python3.5/site-packages/django/db/backends/utils.py", line 64, in execute
    return self.cursor.execute(sql, params)
  File "/home/robert/.virtualenvs/superlists/lib/python3.5/site-packages/django/db/backends/sqlite3/base.py", line 337, in execute
    return Database.Cursor.execute(self, query, params)
django.db.utils.IntegrityError: NOT NULL constraint failed: lists_list.text

======================================================================
ERROR: test_invalid_list_items_arent_saved (lists.tests.test_views.NewListTest)
----------------------------------------------------------------------
Traceback (most recent call last):
  File "/home/robert/.virtualenvs/superlists/lib/python3.5/site-packages/django/db/backends/utils.py", line 64, in execute
    return self.cursor.execute(sql, params)
  File "/home/robert/.virtualenvs/superlists/lib/python3.5/site-packages/django/db/backends/sqlite3/base.py", line 337, in execute
    return Database.Cursor.execute(self, query, params)
sqlite3.IntegrityError: NOT NULL constraint failed: lists_list.text

The above exception was the direct cause of the following exception:

Traceback (most recent call last):
  File "/home/robert/Projects/workspace/superlists/lists/tests/test_views.py", line 103, in test_invalid_list_items_arent_saved
    self.client.post('/lists/new', data={'item_text': ''})
  File "/home/robert/.virtualenvs/superlists/lib/python3.5/site-packages/django/test/client.py", line 541, in post
    secure=secure, **extra)
  File "/home/robert/.virtualenvs/superlists/lib/python3.5/site-packages/django/test/client.py", line 343, in post
    secure=secure, **extra)
  File "/home/robert/.virtualenvs/superlists/lib/python3.5/site-packages/django/test/client.py", line 409, in generic
    return self.request(**r)
  File "/home/robert/.virtualenvs/superlists/lib/python3.5/site-packages/django/test/client.py", line 494, in request
    six.reraise(*exc_info)
  File "/home/robert/.virtualenvs/superlists/lib/python3.5/site-packages/django/utils/six.py", line 686, in reraise
    raise value
  File "/home/robert/.virtualenvs/superlists/lib/python3.5/site-packages/django/core/handlers/exception.py", line 39, in inner
    response = get_response(request)
  File "/home/robert/.virtualenvs/superlists/lib/python3.5/site-packages/django/core/handlers/base.py", line 187, in _get_response
    response = self.process_exception_by_middleware(e, request)
  File "/home/robert/.virtualenvs/superlists/lib/python3.5/site-packages/django/core/handlers/base.py", line 185, in _get_response
    response = wrapped_callback(request, *callback_args, **callback_kwargs)
  File "/home/robert/Projects/workspace/superlists/lists/views.py", line 24, in new_list
    list_ = List.objects.create()
  File "/home/robert/.virtualenvs/superlists/lib/python3.5/site-packages/django/db/models/manager.py", line 85, in manager_method
    return getattr(self.get_queryset(), name)(*args, **kwargs)
  File "/home/robert/.virtualenvs/superlists/lib/python3.5/site-packages/django/db/models/query.py", line 399, in create
    obj.save(force_insert=True, using=self.db)
  File "/home/robert/.virtualenvs/superlists/lib/python3.5/site-packages/django/db/models/base.py", line 796, in save
    force_update=force_update, update_fields=update_fields)
  File "/home/robert/.virtualenvs/superlists/lib/python3.5/site-packages/django/db/models/base.py", line 824, in save_base
    updated = self._save_table(raw, cls, force_insert, force_update, using, update_fields)
  File "/home/robert/.virtualenvs/superlists/lib/python3.5/site-packages/django/db/models/base.py", line 908, in _save_table
    result = self._do_insert(cls._base_manager, using, fields, update_pk, raw)
  File "/home/robert/.virtualenvs/superlists/lib/python3.5/site-packages/django/db/models/base.py", line 947, in _do_insert
    using=using, raw=raw)
  File "/home/robert/.virtualenvs/superlists/lib/python3.5/site-packages/django/db/models/manager.py", line 85, in manager_method
    return getattr(self.get_queryset(), name)(*args, **kwargs)
  File "/home/robert/.virtualenvs/superlists/lib/python3.5/site-packages/django/db/models/query.py", line 1045, in _insert
    return query.get_compiler(using=using).execute_sql(return_id)
  File "/home/robert/.virtualenvs/superlists/lib/python3.5/site-packages/django/db/models/sql/compiler.py", line 1054, in execute_sql
    cursor.execute(sql, params)
  File "/home/robert/.virtualenvs/superlists/lib/python3.5/site-packages/django/db/backends/utils.py", line 64, in execute
    return self.cursor.execute(sql, params)
  File "/home/robert/.virtualenvs/superlists/lib/python3.5/site-packages/django/db/utils.py", line 94, in __exit__
    six.reraise(dj_exc_type, dj_exc_value, traceback)
  File "/home/robert/.virtualenvs/superlists/lib/python3.5/site-packages/django/utils/six.py", line 685, in reraise
    raise value.with_traceback(tb)
  File "/home/robert/.virtualenvs/superlists/lib/python3.5/site-packages/django/db/backends/utils.py", line 64, in execute
    return self.cursor.execute(sql, params)
  File "/home/robert/.virtualenvs/superlists/lib/python3.5/site-packages/django/db/backends/sqlite3/base.py", line 337, in execute
    return Database.Cursor.execute(self, query, params)
django.db.utils.IntegrityError: NOT NULL constraint failed: lists_list.text

======================================================================
ERROR: test_redirects_after_POST (lists.tests.test_views.NewListTest)
----------------------------------------------------------------------
Traceback (most recent call last):
  File "/home/robert/.virtualenvs/superlists/lib/python3.5/site-packages/django/db/backends/utils.py", line 64, in execute
    return self.cursor.execute(sql, params)
  File "/home/robert/.virtualenvs/superlists/lib/python3.5/site-packages/django/db/backends/sqlite3/base.py", line 337, in execute
    return Database.Cursor.execute(self, query, params)
sqlite3.IntegrityError: NOT NULL constraint failed: lists_list.text

The above exception was the direct cause of the following exception:

Traceback (most recent call last):
  File "/home/robert/Projects/workspace/superlists/lists/tests/test_views.py", line 90, in test_redirects_after_POST
    '/lists/new', data = {'item_text': 'A new list item'}
  File "/home/robert/.virtualenvs/superlists/lib/python3.5/site-packages/django/test/client.py", line 541, in post
    secure=secure, **extra)
  File "/home/robert/.virtualenvs/superlists/lib/python3.5/site-packages/django/test/client.py", line 343, in post
    secure=secure, **extra)
  File "/home/robert/.virtualenvs/superlists/lib/python3.5/site-packages/django/test/client.py", line 409, in generic
    return self.request(**r)
  File "/home/robert/.virtualenvs/superlists/lib/python3.5/site-packages/django/test/client.py", line 494, in request
    six.reraise(*exc_info)
  File "/home/robert/.virtualenvs/superlists/lib/python3.5/site-packages/django/utils/six.py", line 686, in reraise
    raise value
  File "/home/robert/.virtualenvs/superlists/lib/python3.5/site-packages/django/core/handlers/exception.py", line 39, in inner
    response = get_response(request)
  File "/home/robert/.virtualenvs/superlists/lib/python3.5/site-packages/django/core/handlers/base.py", line 187, in _get_response
    response = self.process_exception_by_middleware(e, request)
  File "/home/robert/.virtualenvs/superlists/lib/python3.5/site-packages/django/core/handlers/base.py", line 185, in _get_response
    response = wrapped_callback(request, *callback_args, **callback_kwargs)
  File "/home/robert/Projects/workspace/superlists/lists/views.py", line 24, in new_list
    list_ = List.objects.create()
  File "/home/robert/.virtualenvs/superlists/lib/python3.5/site-packages/django/db/models/manager.py", line 85, in manager_method
    return getattr(self.get_queryset(), name)(*args, **kwargs)
  File "/home/robert/.virtualenvs/superlists/lib/python3.5/site-packages/django/db/models/query.py", line 399, in create
    obj.save(force_insert=True, using=self.db)
  File "/home/robert/.virtualenvs/superlists/lib/python3.5/site-packages/django/db/models/base.py", line 796, in save
    force_update=force_update, update_fields=update_fields)
  File "/home/robert/.virtualenvs/superlists/lib/python3.5/site-packages/django/db/models/base.py", line 824, in save_base
    updated = self._save_table(raw, cls, force_insert, force_update, using, update_fields)
  File "/home/robert/.virtualenvs/superlists/lib/python3.5/site-packages/django/db/models/base.py", line 908, in _save_table
    result = self._do_insert(cls._base_manager, using, fields, update_pk, raw)
  File "/home/robert/.virtualenvs/superlists/lib/python3.5/site-packages/django/db/models/base.py", line 947, in _do_insert
    using=using, raw=raw)
  File "/home/robert/.virtualenvs/superlists/lib/python3.5/site-packages/django/db/models/manager.py", line 85, in manager_method
    return getattr(self.get_queryset(), name)(*args, **kwargs)
  File "/home/robert/.virtualenvs/superlists/lib/python3.5/site-packages/django/db/models/query.py", line 1045, in _insert
    return query.get_compiler(using=using).execute_sql(return_id)
  File "/home/robert/.virtualenvs/superlists/lib/python3.5/site-packages/django/db/models/sql/compiler.py", line 1054, in execute_sql
    cursor.execute(sql, params)
  File "/home/robert/.virtualenvs/superlists/lib/python3.5/site-packages/django/db/backends/utils.py", line 64, in execute
    return self.cursor.execute(sql, params)
  File "/home/robert/.virtualenvs/superlists/lib/python3.5/site-packages/django/db/utils.py", line 94, in __exit__
    six.reraise(dj_exc_type, dj_exc_value, traceback)
  File "/home/robert/.virtualenvs/superlists/lib/python3.5/site-packages/django/utils/six.py", line 685, in reraise
    raise value.with_traceback(tb)
  File "/home/robert/.virtualenvs/superlists/lib/python3.5/site-packages/django/db/backends/utils.py", line 64, in execute
    return self.cursor.execute(sql, params)
  File "/home/robert/.virtualenvs/superlists/lib/python3.5/site-packages/django/db/backends/sqlite3/base.py", line 337, in execute
    return Database.Cursor.execute(self, query, params)
django.db.utils.IntegrityError: NOT NULL constraint failed: lists_list.text

======================================================================
ERROR: test_validation_errors_are_sent_to_home_page_template (lists.tests.test_views.NewListTest)
----------------------------------------------------------------------
Traceback (most recent call last):
  File "/home/robert/.virtualenvs/superlists/lib/python3.5/site-packages/django/db/backends/utils.py", line 64, in execute
    return self.cursor.execute(sql, params)
  File "/home/robert/.virtualenvs/superlists/lib/python3.5/site-packages/django/db/backends/sqlite3/base.py", line 337, in execute
    return Database.Cursor.execute(self, query, params)
sqlite3.IntegrityError: NOT NULL constraint failed: lists_list.text

The above exception was the direct cause of the following exception:

Traceback (most recent call last):
  File "/home/robert/Projects/workspace/superlists/lists/tests/test_views.py", line 96, in test_validation_errors_are_sent_to_home_page_template
    response = self.client.post('/lists/new', data={'item_text': ''})
  File "/home/robert/.virtualenvs/superlists/lib/python3.5/site-packages/django/test/client.py", line 541, in post
    secure=secure, **extra)
  File "/home/robert/.virtualenvs/superlists/lib/python3.5/site-packages/django/test/client.py", line 343, in post
    secure=secure, **extra)
  File "/home/robert/.virtualenvs/superlists/lib/python3.5/site-packages/django/test/client.py", line 409, in generic
    return self.request(**r)
  File "/home/robert/.virtualenvs/superlists/lib/python3.5/site-packages/django/test/client.py", line 494, in request
    six.reraise(*exc_info)
  File "/home/robert/.virtualenvs/superlists/lib/python3.5/site-packages/django/utils/six.py", line 686, in reraise
    raise value
  File "/home/robert/.virtualenvs/superlists/lib/python3.5/site-packages/django/core/handlers/exception.py", line 39, in inner
    response = get_response(request)
  File "/home/robert/.virtualenvs/superlists/lib/python3.5/site-packages/django/core/handlers/base.py", line 187, in _get_response
    response = self.process_exception_by_middleware(e, request)
  File "/home/robert/.virtualenvs/superlists/lib/python3.5/site-packages/django/core/handlers/base.py", line 185, in _get_response
    response = wrapped_callback(request, *callback_args, **callback_kwargs)
  File "/home/robert/Projects/workspace/superlists/lists/views.py", line 24, in new_list
    list_ = List.objects.create()
  File "/home/robert/.virtualenvs/superlists/lib/python3.5/site-packages/django/db/models/manager.py", line 85, in manager_method
    return getattr(self.get_queryset(), name)(*args, **kwargs)
  File "/home/robert/.virtualenvs/superlists/lib/python3.5/site-packages/django/db/models/query.py", line 399, in create
    obj.save(force_insert=True, using=self.db)
  File "/home/robert/.virtualenvs/superlists/lib/python3.5/site-packages/django/db/models/base.py", line 796, in save
    force_update=force_update, update_fields=update_fields)
  File "/home/robert/.virtualenvs/superlists/lib/python3.5/site-packages/django/db/models/base.py", line 824, in save_base
    updated = self._save_table(raw, cls, force_insert, force_update, using, update_fields)
  File "/home/robert/.virtualenvs/superlists/lib/python3.5/site-packages/django/db/models/base.py", line 908, in _save_table
    result = self._do_insert(cls._base_manager, using, fields, update_pk, raw)
  File "/home/robert/.virtualenvs/superlists/lib/python3.5/site-packages/django/db/models/base.py", line 947, in _do_insert
    using=using, raw=raw)
  File "/home/robert/.virtualenvs/superlists/lib/python3.5/site-packages/django/db/models/manager.py", line 85, in manager_method
    return getattr(self.get_queryset(), name)(*args, **kwargs)
  File "/home/robert/.virtualenvs/superlists/lib/python3.5/site-packages/django/db/models/query.py", line 1045, in _insert
    return query.get_compiler(using=using).execute_sql(return_id)
  File "/home/robert/.virtualenvs/superlists/lib/python3.5/site-packages/django/db/models/sql/compiler.py", line 1054, in execute_sql
    cursor.execute(sql, params)
  File "/home/robert/.virtualenvs/superlists/lib/python3.5/site-packages/django/db/backends/utils.py", line 64, in execute
    return self.cursor.execute(sql, params)
  File "/home/robert/.virtualenvs/superlists/lib/python3.5/site-packages/django/db/utils.py", line 94, in __exit__
    six.reraise(dj_exc_type, dj_exc_value, traceback)
  File "/home/robert/.virtualenvs/superlists/lib/python3.5/site-packages/django/utils/six.py", line 685, in reraise
    raise value.with_traceback(tb)
  File "/home/robert/.virtualenvs/superlists/lib/python3.5/site-packages/django/db/backends/utils.py", line 64, in execute
    return self.cursor.execute(sql, params)
  File "/home/robert/.virtualenvs/superlists/lib/python3.5/site-packages/django/db/backends/sqlite3/base.py", line 337, in execute
    return Database.Cursor.execute(self, query, params)
django.db.utils.IntegrityError: NOT NULL constraint failed: lists_list.text

----------------------------------------------------------------------
Ran 14 tests in 0.074s

FAILED (errors=13)
Creating test database for alias 'default'...
Destroying test database for alias 'default'...
